<mujocoinclude>
  <body name="fairino_fr5/base_link" pos="0.5 0.5 0">
    <geom type="mesh" mesh="fairino_fr5_1_base_link" name="fairino_fr5/base_link_geom" rgba="0.898 0.917 0.929 1" contype="0" conaffinity="0"/>
    
    <body name="fairino_fr5/shoulder_link" pos="0 0 0.001" gravcomp="1">
      <inertial pos="5.0029e-07 -0.0040922 0.14629" quat="0.999588 0.0287044 7.54149e-06 -1.58789e-05" mass="4.3771" diaginertia="0.010731 0.0104154 0.00817191"/>
      <joint name="fairino_fr5/j1" pos="0 0 0" axis="0 0 1" range="-3.0543 3.0543" limited="true" damping="0.01" frictionloss="50" />
      <geom type="mesh" mesh="fairino_fr5_2_shoulder_link"  name="fairino_fr5/shoulder_link_geom" rgba="0.898 0.917 0.929 1" />
      
      <body name="fairino_fr5/upperarm_link" pos="0 0 0.152" quat="0.499998 0.5 0.5 -0.500002" gravcomp="1">
        <inertial  pos="-0.2125 -5.7643e-09 0.1346" quat="0.5 0.5 0.5 0.5" mass="14.458" diaginertia="0.4559 0.44974 0.028392"/>
        <joint name="fairino_fr5/j2" pos="0 0 0" axis="0 0 1" range="-4.6251 3.14159" limited="true" damping="0.01" frictionloss="60" />
        <geom type="mesh" mesh="fairino_fr5_3_upperarm_link" name="fairino_fr5/upperarm_link_geom" rgba="0.898 0.917 0.929 1" />
        
        <body name="fairino_fr5/forearm_link" pos="-0.425 0 0" quat="0.707105 0 0 0.707108" gravcomp="1">
          <inertial pos="-0.18793 -8.4503e-07 0.0066357" quat="0.510607 0.489172 0.489196 0.510568" mass="7.6737" diaginertia="0.16971 0.168834 0.00821541"/>
          <joint name="fairino_fr5/j3"  pos="0 0 0" axis="0 0 1" range="-3.14159 3.14159" limited="true" damping="0.01" frictionloss="60" />
          <geom type="mesh" mesh="fairino_fr5_4_forearm_link" name="fairino_fr5/forearm_link_geom" rgba="0.898 0.917 0.929 1" />
          
          <body name="fairino_fr5/wrist1_link" pos="-0.39501 0 0" quat="0.707105 0 0 -0.707108" gravcomp="1">
            <inertial pos="4.98e-07 -0.003754 0.097155" quat="0.736149 0.676819 -6.33095e-05 7.15237e-05" mass="1.6266" diaginertia="0.00216 0.00199337 0.00154233" />
            <joint name="fairino_fr5/j4" pos="0 0 0" axis="0 0 1" range="-4.6251 3.14159" limited="true" damping="0.01" frictionloss="30" />
            <geom type="mesh" mesh="fairino_fr5_5_wrist1_link" name="fairino_fr5/wrist1_link_geom" rgba="0.898 0.917 0.929 1" />
            
            <body name="fairino_fr5/wrist2_link" pos="0 0 0.1021" quat="0.499998 0.5 0.5 -0.500002" gravcomp="1">
              <inertial pos="-4.5588e-07 0.0038617 0.098257" quat="0.68712 0.726544 0.000128667 -0.000114125" mass="1.5812" diaginertia="0.0020612 0.00195889 0.00144611" />
              <joint name="fairino_fr5/j5" pos="0 0 0" axis="0 0 1" range="-3.0543 3.0543" limited="true" damping="0.01" frictionloss="30" />
              <geom type="mesh" mesh="fairino_fr5_6_wrist2_link" name="fairino_fr5/wrist2_link_geom" rgba="0.898 0.917 0.929 1" />
              <body name="fairino_fr5/wrist3_link" pos="0 0 0.102" quat="0.707105 -0.707108 0 0" gravcomp="1">
                <body name="vx300s_right/camera_focus" pos="0.15 0 0.01">
                    <site pos="0 0 0" size="0.01" type="sphere" name="right_cam_focus" rgba="0 0 1 0"/>
                </body>
                <site pos="0.15 0 0" size="0.003 0.003 0.03" type="box" name="cali_right_site1" rgba="0 0 1 0"/>
                <site pos="0.15 0 0" size="0.003 0.03 0.003" type="box" name="cali_right_site2" rgba="0 0 1 0"/>
                <site pos="0.15 0 0" size="0.03 0.003 0.003" type="box" name="cali_right_site3" rgba="0 0 1 0"/>
                <camera name="right_wrist" pos="-0.1 0 0.16" fovy="20" mode="targetbody" target="vx300s_right/camera_focus"/>
                <joint name="fairino_fr5/j6" pos="0 0 0" axis="0 0 1" range="-3.0543 3.0543" limited="true" damping="0.1" frictionloss="30" />
                <geom type="mesh" mesh="fairino_fr5_7_wrist3_link" name="fairino_fr5/wrist3_link_geom" rgba="1 0 0 1" />
                <!-- 夹爪底部矩形结构 -->
                <geom pos="0 0 0.05" euler="-1.57 0 0" type="mesh" mesh="vx300s_7_gripper" name="vx300s_right/7_gripper"/>
                <!-- 夹爪滑道 -->
                <geom pos="0 0 0.05" euler="-1.57 0 0" type="mesh" mesh="vx300s_9_gripper_bar" name="vx300s_right/9_gripper_bar"/>
                <!-- 夹爪滑道上方月牙状结构 -->
                <body name="vx300s_right/gripper_prop_link" pos="0.0485 0 0">
                    <inertial pos="0.002378 2.85e-08 0" quat="0 0 0.897698 0.440611" mass="0.008009" diaginertia="4.2979e-06 2.8868e-06 1.5314e-06" />
                    <geom pos="-0.047 0 0.05" euler="-1.57 0 0" type="mesh" mesh="vx300s_8_gripper_prop" rgba="0 0 1 1" name="vx300s_right/8_gripper_prop"/>
                </body>
                <body name="vx300s_right/left_finger_link" pos="0.05 0 0.14" euler="0 0 -1.57" >
                    <inertial pos="0.017344 -0.0060692 0" quat="0.449364 0.449364 -0.54596 -0.54596" mass="0.034796" diaginertia="2.48003e-05 1.417e-05 1.20797e-05" />
                    <joint name="vx300s_right/left_finger" pos="0 0 0" axis="0 -1 0" type="slide" limited="true" range="0.021 0.057" frictionloss="30" />
                    <geom condim="4" solimp="2 1 0.01" solref="0.01 1" friction="1 0.005 0.0001" pos="0 0 0" rgba="0 1 0 1" type="mesh" mesh="vx300s_10_gripper_finger_left" name="vx300s_right/10_left_gripper_finger"/>
                </body>
                <!-- <body name="vx300s_right/right_finger_link" pos="0.05 -0.05 0.0887"> -->
                <body name="vx300s_right/right_finger_link" pos="-0.05 0 0.14" euler="0 0 -1.57" >
                    <inertial pos="0.017344 0.0060692 0" quat="0.44937 -0.44937 0.545955 -0.545955" mass="0.034796" diaginertia="2.48002e-05 1.417e-05 1.20798e-05" />
                    <joint name="vx300s_right/right_finger" pos="0 0 0" axis="0 -1 0" type="slide" limited="true" range="-0.057 -0.021" frictionloss="30" />
                    <geom condim="4" solimp="2 1 0.01" solref="0.01 1" friction="1 0.005 0.0001" pos="0 0 0" rgba="1 0 0 1" type="mesh" mesh="vx300s_10_gripper_finger_right" name="vx300s_right/10_right_gripper_finger"/>
                </body>
              </body>
            </body>
          </body>
        </body>
      </body>
    </body>
  </body>
</mujocoinclude>